<?xml version="1.0" encoding="UTF-8"?>
<testng-results skipped="0" failed="2" ignored="0" total="2" passed="0">
  <reporter-output>
  </reporter-output>
  <suite name="Default suite" duration-ms="26948" started-at="2020-09-29T11:39:53 BST" finished-at="2020-09-29T11:40:20 BST">
    <groups>
    </groups>
    <test name="Default test" duration-ms="26948" started-at="2020-09-29T11:39:53 BST" finished-at="2020-09-29T11:40:20 BST">
      <class name="testNG.FirstTestNG">
        <test-method status="FAIL" signature="testCase1()[pri:0, instance:testNG.FirstTestNG@77ec78b9]" name="testCase1" duration-ms="26867" started-at="2020-09-29T11:39:53 BST" finished-at="2020-09-29T11:40:20 BST">
          <exception class="org.openqa.selenium.remote.UnreachableBrowserException">
            <message>
              <![CDATA[Could not start a new session. Possible causes are invalid address of the remote server or browser start-up failure.
Build info: version: '4.0.0-alpha-5', revision: 'b3a0d621cc'
System info: host: 'LAPTOP-H4ODDOJJ', ip: '172.19.128.1', os.name: 'Windows 10', os.arch: 'amd64', os.version: '10.0', java.version: '1.8.0_211'
Driver info: driver.version: RemoteWebDriver]]>
            </message>
            <full-stacktrace>
              <![CDATA[org.openqa.selenium.remote.UnreachableBrowserException: Could not start a new session. Possible causes are invalid address of the remote server or browser start-up failure.
Build info: version: '4.0.0-alpha-5', revision: 'b3a0d621cc'
System info: host: 'LAPTOP-H4ODDOJJ', ip: '172.19.128.1', os.name: 'Windows 10', os.arch: 'amd64', os.version: '10.0', java.version: '1.8.0_211'
Driver info: driver.version: RemoteWebDriver
at org.openqa.selenium.remote.RemoteWebDriver.execute(RemoteWebDriver.java:603)
at org.openqa.selenium.remote.RemoteWebDriver.startSession(RemoteWebDriver.java:216)
at org.openqa.selenium.remote.RemoteWebDriver.<init>(RemoteWebDriver.java:136)
at org.openqa.selenium.remote.RemoteWebDriver.<init>(RemoteWebDriver.java:149)
at testNG.FirstTestNG.testCase1(FirstTestNG.java:33)
at sun.reflect.NativeMethodAccessorImpl.invoke0(Native Method)
at sun.reflect.NativeMethodAccessorImpl.invoke(NativeMethodAccessorImpl.java:62)
at sun.reflect.DelegatingMethodAccessorImpl.invoke(DelegatingMethodAccessorImpl.java:43)
at java.lang.reflect.Method.invoke(Method.java:498)
at org.testng.internal.MethodInvocationHelper.invokeMethod(MethodInvocationHelper.java:132)
at org.testng.internal.TestInvoker.invokeMethod(TestInvoker.java:599)
at org.testng.internal.TestInvoker.invokeTestMethod(TestInvoker.java:174)
at org.testng.internal.MethodRunner.runInSequence(MethodRunner.java:46)
at org.testng.internal.TestInvoker$MethodInvocationAgent.invoke(TestInvoker.java:822)
at org.testng.internal.TestInvoker.invokeTestMethods(TestInvoker.java:147)
at org.testng.internal.TestMethodWorker.invokeTestMethods(TestMethodWorker.java:146)
at org.testng.internal.TestMethodWorker.run(TestMethodWorker.java:128)
at java.util.ArrayList.forEach(ArrayList.java:1257)
at org.testng.TestRunner.privateRun(TestRunner.java:764)
at org.testng.TestRunner.run(TestRunner.java:585)
at org.testng.SuiteRunner.runTest(SuiteRunner.java:384)
at org.testng.SuiteRunner.runSequentially(SuiteRunner.java:378)
at org.testng.SuiteRunner.privateRun(SuiteRunner.java:337)
at org.testng.SuiteRunner.run(SuiteRunner.java:286)
at org.testng.SuiteRunnerWorker.runSuite(SuiteRunnerWorker.java:53)
at org.testng.SuiteRunnerWorker.run(SuiteRunnerWorker.java:96)
at org.testng.TestNG.runSuitesSequentially(TestNG.java:1218)
at org.testng.TestNG.runSuitesLocally(TestNG.java:1140)
at org.testng.TestNG.runSuites(TestNG.java:1069)
at org.testng.TestNG.run(TestNG.java:1037)
at org.testng.remote.AbstractRemoteTestNG.run(AbstractRemoteTestNG.java:115)
at org.testng.remote.RemoteTestNG.initAndRun(RemoteTestNG.java:251)
at org.testng.remote.RemoteTestNG.main(RemoteTestNG.java:77)
Caused by: java.io.UncheckedIOException: java.net.ConnectException: Connection refused: no further information: localhost/0:0:0:0:0:0:0:1:4444
at org.openqa.selenium.remote.http.netty.NettyHttpHandler.makeCall(NettyHttpHandler.java:69)
at org.openqa.selenium.remote.http.AddSeleniumUserAgent.lambda$apply$0(AddSeleniumUserAgent.java:42)
at org.openqa.selenium.remote.http.Filter.lambda$andFinally$1(Filter.java:55)
at org.openqa.selenium.remote.http.netty.NettyHttpHandler.execute(NettyHttpHandler.java:47)
at org.openqa.selenium.remote.http.AddSeleniumUserAgent.lambda$apply$0(AddSeleniumUserAgent.java:42)
at org.openqa.selenium.remote.http.Filter.lambda$andFinally$1(Filter.java:55)
at org.openqa.selenium.remote.http.netty.NettyClient.execute(NettyClient.java:47)
at org.openqa.selenium.remote.ProtocolHandshake.createSession(ProtocolHandshake.java:105)
at org.openqa.selenium.remote.ProtocolHandshake.createSession(ProtocolHandshake.java:75)
at org.openqa.selenium.remote.HttpCommandExecutor.execute(HttpCommandExecutor.java:139)
at org.openqa.selenium.remote.RemoteWebDriver.execute(RemoteWebDriver.java:582)
... 32 more
Caused by: java.net.ConnectException: Connection refused: no further information: localhost/0:0:0:0:0:0:0:1:4444
at org.asynchttpclient.netty.channel.NettyConnectListener.onFailure(NettyConnectListener.java:179)
at org.asynchttpclient.netty.channel.NettyChannelConnector$1.onFailure(NettyChannelConnector.java:108)
at org.asynchttpclient.netty.SimpleChannelFutureListener.operationComplete(SimpleChannelFutureListener.java:28)
at org.asynchttpclient.netty.SimpleChannelFutureListener.operationComplete(SimpleChannelFutureListener.java:20)
at io.netty.util.concurrent.DefaultPromise.notifyListener0(DefaultPromise.java:577)
at io.netty.util.concurrent.DefaultPromise.notifyListeners0(DefaultPromise.java:570)
at io.netty.util.concurrent.DefaultPromise.notifyListenersNow(DefaultPromise.java:549)
at io.netty.util.concurrent.DefaultPromise.notifyListeners(DefaultPromise.java:490)
at io.netty.util.concurrent.DefaultPromise.setValue0(DefaultPromise.java:615)
at io.netty.util.concurrent.DefaultPromise.setFailure0(DefaultPromise.java:608)
at io.netty.util.concurrent.DefaultPromise.tryFailure(DefaultPromise.java:117)
at io.netty.channel.nio.AbstractNioChannel$AbstractNioUnsafe.fulfillConnectPromise(AbstractNioChannel.java:321)
at io.netty.channel.nio.AbstractNioChannel$AbstractNioUnsafe.finishConnect(AbstractNioChannel.java:337)
at io.netty.channel.nio.NioEventLoop.processSelectedKey(NioEventLoop.java:702)
at io.netty.channel.nio.NioEventLoop.processSelectedKeysOptimized(NioEventLoop.java:650)
at io.netty.channel.nio.NioEventLoop.processSelectedKeys(NioEventLoop.java:576)
at io.netty.channel.nio.NioEventLoop.run(NioEventLoop.java:493)
at io.netty.util.concurrent.SingleThreadEventExecutor$4.run(SingleThreadEventExecutor.java:989)
at io.netty.util.internal.ThreadExecutorMap$2.run(ThreadExecutorMap.java:74)
at io.netty.util.concurrent.FastThreadLocalRunnable.run(FastThreadLocalRunnable.java:30)
at java.lang.Thread.run(Thread.java:748)
Caused by: io.netty.channel.AbstractChannel$AnnotatedConnectException: Connection refused: no further information: localhost/0:0:0:0:0:0:0:1:4444
Caused by: java.net.ConnectException: Connection refused: no further information
at sun.nio.ch.SocketChannelImpl.checkConnect(Native Method)
at sun.nio.ch.SocketChannelImpl.finishConnect(SocketChannelImpl.java:717)
at io.netty.channel.socket.nio.NioSocketChannel.doFinishConnect(NioSocketChannel.java:330)
at io.netty.channel.nio.AbstractNioChannel$AbstractNioUnsafe.finishConnect(AbstractNioChannel.java:334)
at io.netty.channel.nio.NioEventLoop.processSelectedKey(NioEventLoop.java:702)
at io.netty.channel.nio.NioEventLoop.processSelectedKeysOptimized(NioEventLoop.java:650)
at io.netty.channel.nio.NioEventLoop.processSelectedKeys(NioEventLoop.java:576)
at io.netty.channel.nio.NioEventLoop.run(NioEventLoop.java:493)
at io.netty.util.concurrent.SingleThreadEventExecutor$4.run(SingleThreadEventExecutor.java:989)
at io.netty.util.internal.ThreadExecutorMap$2.run(ThreadExecutorMap.java:74)
at io.netty.util.concurrent.FastThreadLocalRunnable.run(FastThreadLocalRunnable.java:30)
at java.lang.Thread.run(Thread.java:748)
]]>
            </full-stacktrace>
          </exception> <!-- org.openqa.selenium.remote.UnreachableBrowserException -->
          <reporter-output>
          </reporter-output>
        </test-method> <!-- testCase1 -->
        <test-method status="FAIL" signature="testCase2()[pri:0, instance:testNG.FirstTestNG@77ec78b9]" name="testCase2" duration-ms="7" started-at="2020-09-29T11:40:20 BST" finished-at="2020-09-29T11:40:20 BST">
          <exception class="java.lang.AssertionError">
            <message>
              <![CDATA[expected [false] but found [true]]]>
            </message>
            <full-stacktrace>
              <![CDATA[java.lang.AssertionError: expected [false] but found [true]
at org.testng.Assert.fail(Assert.java:99)
at org.testng.Assert.failNotEquals(Assert.java:1037)
at org.testng.Assert.assertFalse(Assert.java:67)
at org.testng.Assert.assertFalse(Assert.java:77)
at testNG.FirstTestNG.testCase2(FirstTestNG.java:53)
at sun.reflect.NativeMethodAccessorImpl.invoke0(Native Method)
at sun.reflect.NativeMethodAccessorImpl.invoke(NativeMethodAccessorImpl.java:62)
at sun.reflect.DelegatingMethodAccessorImpl.invoke(DelegatingMethodAccessorImpl.java:43)
at java.lang.reflect.Method.invoke(Method.java:498)
at org.testng.internal.MethodInvocationHelper.invokeMethod(MethodInvocationHelper.java:132)
at org.testng.internal.TestInvoker.invokeMethod(TestInvoker.java:599)
at org.testng.internal.TestInvoker.invokeTestMethod(TestInvoker.java:174)
at org.testng.internal.MethodRunner.runInSequence(MethodRunner.java:46)
at org.testng.internal.TestInvoker$MethodInvocationAgent.invoke(TestInvoker.java:822)
at org.testng.internal.TestInvoker.invokeTestMethods(TestInvoker.java:147)
at org.testng.internal.TestMethodWorker.invokeTestMethods(TestMethodWorker.java:146)
at org.testng.internal.TestMethodWorker.run(TestMethodWorker.java:128)
at java.util.ArrayList.forEach(ArrayList.java:1257)
at org.testng.TestRunner.privateRun(TestRunner.java:764)
at org.testng.TestRunner.run(TestRunner.java:585)
at org.testng.SuiteRunner.runTest(SuiteRunner.java:384)
at org.testng.SuiteRunner.runSequentially(SuiteRunner.java:378)
at org.testng.SuiteRunner.privateRun(SuiteRunner.java:337)
at org.testng.SuiteRunner.run(SuiteRunner.java:286)
at org.testng.SuiteRunnerWorker.runSuite(SuiteRunnerWorker.java:53)
at org.testng.SuiteRunnerWorker.run(SuiteRunnerWorker.java:96)
at org.testng.TestNG.runSuitesSequentially(TestNG.java:1218)
at org.testng.TestNG.runSuitesLocally(TestNG.java:1140)
at org.testng.TestNG.runSuites(TestNG.java:1069)
at org.testng.TestNG.run(TestNG.java:1037)
at org.testng.remote.AbstractRemoteTestNG.run(AbstractRemoteTestNG.java:115)
at org.testng.remote.RemoteTestNG.initAndRun(RemoteTestNG.java:251)
at org.testng.remote.RemoteTestNG.main(RemoteTestNG.java:77)
]]>
            </full-stacktrace>
          </exception> <!-- java.lang.AssertionError -->
          <reporter-output>
          </reporter-output>
        </test-method> <!-- testCase2 -->
      </class> <!-- testNG.FirstTestNG -->
    </test> <!-- Default test -->
  </suite> <!-- Default suite -->
</testng-results>
